Workbook

Sheet Summary
A1: Konbaung Chronicle knowledge graph: extraction evaluation
A2: Two independent random samples of 61 pages each (122 of 1,215 pages; 1,201 sentences; 2,808 extracted triples). Judge: ChatGPT (OpenAI), reading each sampled Burmese sentence with its surrounding narrative. Extraction model: Gemini 3.1 Flash Lite.
A4: Measure | B4: First 5% | C4: Second 5% | D4: Combined | E4: Definition
A5: Triples judged | B5: =COUNTIF(Triples!$A$2:$A$2809,"First 5%") -> 1423 | C5: =COUNTIF(Triples!$A$2:$A$2809,"Second 5%") -> 1385 | D5: =COUNTA(Triples!$A$2:$A$2809) -> 2808 | E5: Extracted subject–predicate–object triples on the sampled pages
A6: Supported | B6: =COUNTIFS(Triples!$A$2:$A$2809,"First 5%",Triples!$I$2:$I$2809,"supported") -> 1339 | C6: =COUNTIFS(Triples!$A$2:$A$2809,"Second 5%",Triples!$I$2:$I$2809,"supported") -> 1285 | D6: =COUNTIF(Triples!$I$2:$I$2809,"supported") -> 2624 | E6: Relationship, actor, action and object supported by the Burmese and narrative context
A7: Soft error | B7: =COUNTIFS(Triples!$A$2:$A$2809,"First 5%",Triples!$I$2:$I$2809,"soft") -> 37 | C7: =COUNTIFS(Triples!$A$2:$A$2809,"Second 5%",Triples!$I$2:$I$2809,"soft") -> 48 | D7: =COUNTIF(Triples!$I$2:$I$2809,"soft") -> 85 | E7: Relationship true; a construction, label or detail needs repair
A8: Hard error | B8: =COUNTIFS(Triples!$A$2:$A$2809,"First 5%",Triples!$I$2:$I$2809,"hard") -> 45 | C8: =COUNTIFS(Triples!$A$2:$A$2809,"Second 5%",Triples!$I$2:$I$2809,"hard") -> 48 | D8: =COUNTIF(Triples!$I$2:$I$2809,"hard") -> 93 | E8: A substantive claim conflicts with the source (wrong actor, place, event, direction or office)
A9: Unresolved | B9: =COUNTIFS(Triples!$A$2:$A$2809,"First 5%",Triples!$I$2:$I$2809,"uncertain") -> 2 | C9: =COUNTIFS(Triples!$A$2:$A$2809,"Second 5%",Triples!$I$2:$I$2809,"uncertain") -> 4 | D9: =COUNTIF(Triples!$I$2:$I$2809,"uncertain") -> 6 | E9: Two readings possible; not counted as correct or as an error
A10: Semantic precision | B10: =(B6+B7)/B5 -> 0.96697119 | C10: =(C6+C7)/C5 -> 0.96245487 | D10: =(D6+D7)/D5 -> 0.96474359 | E10: (Supported + Soft) / Triples judged
A11: No-flag precision | B11: =B6/B5 -> 0.94096978 | C11: =C6/C5 -> 0.92779783 | D11: =D6/D5 -> 0.93447293 | E11: Supported / Triples judged
A12: Hard error rate | B12: =B8/B5 -> 0.031623331 | C12: =C8/C5 -> 0.03465704 | D12: =D8/D5 -> 0.033119658 | E12: Hard / Triples judged
A13: Source relationships | B13: =COUNTIFS(Recall!$A$2:$A$1523,"First 5%",Recall!$H$2:$H$1523,"yes") -> 757 | C13: =COUNTIFS(Recall!$A$2:$A$1523,"Second 5%",Recall!$H$2:$H$1523,"yes") -> 757 | D13: =COUNTIF(Recall!$H$2:$H$1523,"yes") -> 1514 | E13: Relationships the judge identified in the Burmese, on pages with extraction output
A14: Covered | B14: =COUNTIFS(Recall!$A$2:$A$1523,"First 5%",Recall!$G$2:$G$1523,"covered",Recall!$H$2:$H$1523,"yes") -> 677 | C14: =COUNTIFS(Recall!$A$2:$A$1523,"Second 5%",Recall!$G$2:$G$1523,"covered",Recall!$H$2:$H$1523,"yes") -> 675 | D14: =COUNTIFS(Recall!$G$2:$G$1523,"covered",Recall!$H$2:$H$1523,"yes") -> 1352 | E14: Represented adequately by one or more triples
A15: Partial | B15: =COUNTIFS(Recall!$A$2:$A$1523,"First 5%",Recall!$G$2:$G$1523,"partial",Recall!$H$2:$H$1523,"yes") -> 24 | C15: =COUNTIFS(Recall!$A$2:$A$1523,"Second 5%",Recall!$G$2:$G$1523,"partial",Recall!$H$2:$H$1523,"yes") -> 22 | D15: =COUNTIFS(Recall!$G$2:$G$1523,"partial",Recall!$H$2:$H$1523,"yes") -> 46 | E15: Represented, but a substantive aspect is missing
A16: Incorrect | B16: =COUNTIFS(Recall!$A$2:$A$1523,"First 5%",Recall!$G$2:$G$1523,"incorrect",Recall!$H$2:$H$1523,"yes") -> 17 | C16: =COUNTIFS(Recall!$A$2:$A$1523,"Second 5%",Recall!$G$2:$G$1523,"incorrect",Recall!$H$2:$H$1523,"yes") -> 27 | D16: =COUNTIFS(Recall!$G$2:$G$1523,"incorrect",Recall!$H$2:$H$1523,"yes") -> 44 | E16: Represented, but wrongly
A17: Missing | B17: =COUNTIFS(Recall!$A$2:$A$1523,"First 5%",Recall!$G$2:$G$1523,"missing",Recall!$H$2:$H$1523,"yes") -> 39 | C17: =COUNTIFS(Recall!$A$2:$A$1523,"Second 5%",Recall!$G$2:$G$1523,"missing",Recall!$H$2:$H$1523,"yes") -> 33 | D17: =COUNTIFS(Recall!$G$2:$G$1523,"missing",Recall!$H$2:$H$1523,"yes") -> 72 | E17: Not represented
A18: Inclusive recall | B18: =(B14+B15)/B13 -> 0.92602378 | C18: =(C14+C15)/C13 -> 0.92073976 | D18: =(D14+D15)/D13 -> 0.92338177 | E18: (Covered + Partial) / Source relationships
A19: Full-only recall | B19: =B14/B13 -> 0.89431968 | C19: =C14/C13 -> 0.89167768 | D19: =D14/D13 -> 0.89299868 | E19: Covered / Source relationships
A21: 95% intervals (page-cluster bootstrap, 20,000 resamples)
A22: Semantic precision | B22: 94.7–98.3% | C22: 94.3–97.8% | D22: 95.1–97.6%
A23: Inclusive recall | B23: 89.4–95.4% | C23: 89.7–94.4% | D23: 90.4–94.2%
A24: Full-only recall | B24: 86.3–92.3% | C24: 86.4–91.8% | D24: 87.2–91.2%
A25: Intervals are copied from the audit records (metrics_final.json) and reflect sampling variation only.
A27: Notes
A28: The judge credits reasonable grouping, paraphrase and contextually supplied actors. Claims are judged against what the chronicle says, not against external historical fact.
A29: Precision is measured per triple; recall per source relationship. The two use different units, so no F1 is reported.
A30: Volume 3, page 511 (second sample) has no extraction output; its 8 source relationships are excluded from recall above. Including them, combined inclusive recall is 91.9%.
A31: Samples: first drawn with seed 20260915; second with seed 20260916 from the remaining pages.
A32: English translations are the pipeline's model translations, shown for convenience; the judge worked from the Burmese.
A33: Sheets: Triples (every judged triple), Recall (every source relationship and its matching triples), Sentences (every sampled sentence).

Sheet Triples
A1: Tranche | B1: Volume | C1: Page | D1: Sentence ID | E1: Triple ID | F1: Subject | G1: Predicate | H1: Object | I1: Verdict | J1: Judge reasoning | K1: Suggested correction | L1: Burmese sentence | M1: English translation (auxiliary)
A2: First 5% | B2: vol1 | C2: 71 | D2: vol1_s000407 | E2: vol1_s000407_t01_3c02a13d586a | F2: Alaungmintayagyi | G2: PERFORMED_RITUAL_DEPARTURE_FROM | H2: Cittakuta_gate | I2: hard | J2: The Cittakuta gate belongs to the comparison with Sakra, not to the king’s actual departure. The king leaves through the eastern right-hand gate. The triple literalizes the simile. | K2: Alaungmintayagyi | DEPARTED_THROUGH | eastern right-hand gate (or retain Cittakuta explicitly as a simile) | L2: ထိုအခါ အလောင်းမင်းတရားကြီး ဘုရားလည်း သက္ကရာဇ် တစ်ထောင့် တစ်ရာ့ လေးဆယ့် လေးခု၊ ကဆုန်လပြည့်ကျော်ရှစ်ရက် သောကြာနေ့၊ မွန်းယိမ်းနှစ်ချက်တီးကျော် နှစ်မောင်းတွင် အတန္တုအားဖြင့် တာဝတိံသာ မဟာသုဒဿနမြို့သို့ ချီတက်လာကုန်သော အသူရာစစ်သည်တို့ကို နှိပ်နင်းအံ့သောငှာ မင်္ဂလာရှိသော စိတ္တကုဋ် တံခါးမှ သိကြားထွက်စံသကဲ့သို့ အောင်တံခွန်ကို လွှားလွှားလွှင့်တော်မူ၍ သားတော်မြတ် နှစ်ပါးနှင့်တကွ ဆွေတော် မျိုးတော် ကျွန်တော်ရင်း မြင်းရည်တက် လေးဆယ့်ခြောက်ခေါင်း အစု အမှုထမ်း လက်နက်စွဲ သူရဲအပေါင်း ခြံရံလျက် မင်းတို့စံပယ်ခြင်းဖြင့် စည်တော်ရွမ်း၍ အရှေ့မျက်နှာ လက်ယာတံခါးမှ ရွှေထီးဖြန့်လျက် ထွက်တော် မူသည်ကို မွန်တို့တပ်က မြင်လျှင် သောသောထ၍ ကြည့်ကြစဉ် ကောင်းကင်အရပ်က သိမ်းငှက်တစ်ခုသည် စွန်ရဲကို တိုက်၍ ရှေ့တော်တူရူ ဦးခေါင်းငိုက်ဆိုက် ကျလာသည်ကို ရဲမက်တော်တို့ လှံနှင့်နှိပ်၍ ရလိုက်သည်။ | M2: At that time, Alaungmintayagyi Paya, in the year 1144, on the eighth day of the waning moon of Kason, a Friday, at the time just past two strokes of the afternoon, in order to suppress the Asura soldiers who were marching toward the Tavatimsa Mahasudassana city as if by analogy, raised the victory banner high as if Sakra were emerging from the auspicious Cittakuta gate, and surrounded by his two noble sons, his relatives, his kin, his loyal servants, forty-six cavalrymen, and all the armed soldiers and service personnel, with the royal drums beating in the royal manner, he emerged from the right gate on the eastern side with the golden umbrella spread; when the Mon army saw this, they rose up in a clamor to watch, and at that moment, a hawk from the sky attacked a kite, and it fell headlong directly in front of him, which the royal soldiers struck with spears and caught.
A3: First 5% | B3: vol1 | C3: 71 | D3: vol1_s000407 | E3: vol1_s000407_t02_97f3bf59b463 | F3: Alaungmintayagyi | G3: DISPLAYED_ROYAL_REGALIA | H3: victory_banner_and_golden_umbrella | I3: supported | J3: Supported by the Burmese sentence and allowed narrative context; grouping and contextually inferred participants accepted. | L3: ထိုအခါ အလောင်းမင်းတရားကြီး ဘုရားလည်း သက္ကရာဇ် တစ်ထောင့် တစ်ရာ့ လေးဆယ့် လေးခု၊ ကဆုန်လပြည့်ကျော်ရှစ်ရက် သောကြာနေ့၊ မွန်းယိမ်းနှစ်ချက်တီးကျော် နှစ်မောင်းတွင် အတန္တုအားဖြင့် တာဝတိံသာ မဟာသုဒဿနမြို့သို့ ချီတက်လာကုန်သော အသူရာစစ်သည်တို့ကို နှိပ်နင်းအံ့သောငှာ မင်္ဂလာရှိသော စိတ္တကုဋ် တံခါးမှ သိကြားထွက်စံသကဲ့သို့ အောင်တံခွန်ကို လွှားလွှားလွှင့်တော်မူ၍ သားတော်မြတ် နှစ်ပါးနှင့်တကွ ဆွေတော် မျိုးတော် ကျွန်တော်ရင်း မြင်းရည်တက် လေးဆယ့်ခြောက်ခေါင်း အစု အမှုထမ်း လက်နက်စွဲ သူရဲအပေါင်း ခြံရံလျက် မင်းတို့စံပယ်ခြင်းဖြင့် စည်တော်ရွမ်း၍ အရှေ့မျက်နှာ လက်ယာတံခါးမှ ရွှေထီးဖြန့်လျက် ထွက်တော် မူသည်ကို မွန်တို့တပ်က မြင်လျှင် သောသောထ၍ ကြည့်ကြစဉ် ကောင်းကင်အရပ်က သိမ်းငှက်တစ်ခုသည် စွန်ရဲကို တိုက်၍ ရှေ့တော်တူရူ ဦးခေါင်းငိုက်ဆိုက် ကျလာသည်ကို ရဲမက်တော်တို့ လှံနှင့်နှိပ်၍ ရလိုက်သည်။ | M3: At that time, Alaungmintayagyi Paya, in the year 1144, on the eighth day of the waning moon of Kason, a Friday, at the time just past two strokes of the afternoon, in order to suppress the Asura soldiers who were marching toward the Tavatimsa Mahasudassana city as if by analogy, raised the victory banner high as if Sakra were emerging from the auspicious Cittakuta gate, and surrounded by his two noble sons, his relatives, his kin, his loyal servants, forty-six cavalrymen, and all the armed soldiers and service personnel, with the royal drums beating in the royal manner, he emerged from the right gate on the eastern side with the golden umbrella spread; when the Mon army saw this, they rose up in a clamor to watch, and at that moment, a hawk from the sky attacked a kite, and it fell headlong directly in front of him, which the royal soldiers struck with spears and caught.
A4: First 5% | B4: vol1 | C4: 71 | D4: vol1_s000407 | E4: vol1_s000407_t03_0be63211651d | F4: Alaungmintayagyi | G4: MOBILIZED_MILITARY_ASSETS | H4: cavalry_and_armed_soldiers | I4: supported | J4: Supported by the Burmese sentence and allowed narrative context; grouping and contextually inferred participants accepted. | L4: ထိုအခါ အလောင်းမင်းတရားကြီး ဘုရားလည်း သက္ကရာဇ် တစ်ထောင့် တစ်ရာ့ လေးဆယ့် လေးခု၊ ကဆုန်လပြည့်ကျော်ရှစ်ရက် သောကြာနေ့၊ မွန်းယိမ်းနှစ်ချက်တီးကျော် နှစ်မောင်းတွင် အတန္တုအားဖြင့် တာဝတိံသာ မဟာသုဒဿနမြို့သို့ ချီတက်လာကုန်သော အသူရာစစ်သည်တို့ကို နှိပ်နင်းအံ့သောငှာ မင်္ဂလာရှိသော စိတ္တကုဋ် တံခါးမှ သိကြားထွက်စံသကဲ့သို့ အောင်တံခွန်ကို လွှားလွှားလွှင့်တော်မူ၍ သားတော်မြတ် နှစ်ပါးနှင့်တကွ ဆွေတော် မျိုးတော် ကျွန်တော်ရင်း မြင်းရည်တက် လေးဆယ့်ခြောက်ခေါင်း အစု အမှုထမ်း လက်နက်စွဲ သူရဲအပေါင်း ခြံရံလျက် မင်းတို့စံပယ်ခြင်းဖြင့် စည်တော်ရွမ်း၍ အရှေ့မျက်နှာ လက်ယာတံခါးမှ ရွှေထီးဖြန့်လျက် ထွက်တော် မူသည်ကို မွန်တို့တပ်က မြင်လျှင် သောသောထ၍ ကြည့်ကြစဉ် ကောင်းကင်အရပ်က သိမ်းငှက်တစ်ခုသည် စွန်ရဲကို တိုက်၍ ရှေ့တော်တူရူ ဦးခေါင်းငိုက်ဆိုက် ကျလာသည်ကို ရဲမက်တော်တို့ လှံနှင့်နှိပ်၍ ရလိုက်သည်။ | M4: At that time, Alaungmintayagyi Paya, in the year 1144, on the eighth day of the waning moon of Kason, a Friday, at the time just past two strokes of the afternoon, in order to suppress the Asura soldiers who were marching toward the Tavatimsa Mahasudassana city as if by analogy, raised the victory banner high as if Sakra were emerging from the auspicious Cittakuta gate, and surrounded by his two noble sons, his relatives, his kin, his loyal servants, forty-six cavalrymen, and all the armed soldiers and service personnel, with the royal drums beating in the royal manner, he emerged from the right gate on the eastern side with the golden umbrella spread; when the Mon army saw this, they rose up in a clamor to watch, and at that moment, a hawk from the sky attacked a kite, and it fell headlong directly in front of him, which the royal soldiers struck with spears and caught.
A5: First 5% | B5: vol1 | C5: 71 | D5: vol1_s000407 | E5: vol1_s000407_t04_d0b57d421653 | F5: Alaungmintayagyi | G5: COMMANDED_LOYALTY_OF | H5: sons_and_kin_and_servants | I5: supported | J5: Supported by the Burmese sentence and allowed narrative context; grouping and contextually inferred participants accepted. | L5: ထိုအခါ အလောင်းမင်းတရားကြီး ဘုရားလည်း သက္ကရာဇ် တစ်ထောင့် တစ်ရာ့ လေးဆယ့် လေးခု၊ ကဆုန်လပြည့်ကျော်ရှစ်ရက် သောကြာနေ့၊ မွန်းယိမ်းနှစ်ချက်တီးကျော် နှစ်မောင်းတွင် အတန္တုအားဖြင့် တာဝတိံသာ မဟာသုဒဿနမြို့သို့ ချီတက်လာကုန်သော အသူရာစစ်သည်တို့ကို နှိပ်နင်းအံ့သောငှာ မင်္ဂလာရှိသော စိတ္တကုဋ် တံခါးမှ သိကြားထွက်စံသကဲ့သို့ အောင်တံခွန်ကို လွှားလွှားလွှင့်တော်မူ၍ သားတော်မြတ် နှစ်ပါးနှင့်တကွ ဆွေတော် မျိုးတော် ကျွန်တော်ရင်း မြင်းရည်တက် လေးဆယ့်ခြောက်ခေါင်း အစု အမှုထမ်း လက်နက်စွဲ သူရဲအပေါင်း ခြံရံလျက် မင်းတို့စံပယ်ခြင်းဖြင့် စည်တော်ရွမ်း၍ အရှေ့မျက်နှာ လက်ယာတံခါးမှ ရွှေထီးဖြန့်လျက် ထွက်တော် မူသည်ကို မွန်တို့တပ်က မြင်လျှင် သောသောထ၍ ကြည့်ကြစဉ် ကောင်းကင်အရပ်က သိမ်းငှက်တစ်ခုသည် စွန်ရဲကို တိုက်၍ ရှေ့တော်တူရူ ဦးခေါင်းငိုက်ဆိုက် ကျလာသည်ကို ရဲမက်တော်တို့ လှံနှင့်နှိပ်၍ ရလိုက်သည်။ | M5: At that time, Alaungmintayagyi Paya, in the year 1144, on the eighth day of the waning moon of Kason, a Friday, at the time just past two strokes of the afternoon, in order to suppress the Asura soldiers who were marching toward the Tavatimsa Mahasudassana city as if by analogy, raised the victory banner high as if Sakra were emerging from the auspicious Cittakuta gate, and surrounded by his two noble sons, his relatives, his kin, his loyal servants, forty-six cavalrymen, and all the armed soldiers and service personnel, with the royal drums beating in the royal manner, he emerged from the right gate on the eastern side with the golden umbrella spread; when the Mon army saw this, they rose up in a clamor to watch, and at that moment, a hawk from the sky attacked a kite, and it fell headlong directly in front of him, which the royal soldiers struck with spears and caught.
A6: First 5% | B6: vol1 | C6: 71 | D6: vol1_s000407 | E6: vol1_s000407_t05_008bb89c30b3 | F6: Mon_army | G6: OBSERVED_ROYAL_DISPLAY_OF | H6: Alaungmintayagyi | I6: supported | J6: Supported by the Burmese sentence and allowed narrative context; grouping and contextually inferred participants accepted. | L6: ထိုအခါ အလောင်းမင်းတရားကြီး ဘုရားလည်း သက္ကရာဇ် တစ်ထောင့် တစ်ရာ့ လေးဆယ့် လေးခု၊ ကဆုန်လပြည့်ကျော်ရှစ်ရက် သောကြာနေ့၊ မွန်းယိမ်းနှစ်ချက်တီးကျော် နှစ်မောင်းတွင် အတန္တုအားဖြင့် တာဝတိံသာ မဟာသုဒဿနမြို့သို့ ချီတက်လာကုန်သော အသူရာစစ်သည်တို့ကို နှိပ်နင်းအံ့သောငှာ မင်္ဂလာရှိသော စိတ္တကုဋ် တံခါးမှ သိကြားထွက်စံသကဲ့သို့ အောင်တံခွန်ကို လွှားလွှားလွှင့်တော်မူ၍ သားတော်မြတ် နှစ်ပါးနှင့်တကွ ဆွေတော် မျိုးတော် ကျွန်တော်ရင်း မြင်းရည်တက် လေးဆယ့်ခြောက်ခေါင်း အစု အမှုထမ်း လက်နက်စွဲ သူရဲအပေါင်း ခြံရံလျက် မင်းတို့စံပယ်ခြင်းဖြင့် စည်တော်ရွမ်း၍ အရှေ့မျက်နှာ လက်ယာတံခါးမှ ရွှေထီးဖြန့်လျက် ထွက်တော် မူသည်ကို မွန်တို့တပ်က မြင်လျှင် သောသောထ၍ ကြည့်ကြစဉ် ကောင်းကင်အရပ်က သိမ်းငှက်တစ်ခုသည် စွန်ရဲကို တိုက်၍ ရှေ့တော်တူရူ ဦးခေါင်းငိုက်ဆိုက် ကျလာသည်ကို ရဲမက်တော်တို့ လှံနှင့်နှိပ်၍ ရလိုက်သည်။ | M6: At that time, Alaungmintayagyi Paya, in the year 1144, on the eighth day of the waning moon of Kason, a Friday, at the time just past two strokes of the afternoon, in order to suppress the Asura soldiers who were marching toward the Tavatimsa Mahasudassana city as if by analogy, raised the victory banner high as if Sakra were emerging from the auspicious Cittakuta gate, and surrounded by his two noble sons, his relatives, his kin, his loyal servants, forty-six cavalrymen, and all the armed soldiers and service personnel, with the royal drums beating in the royal manner, he emerged from the right gate on the eastern side with the golden umbrella spread; when the Mon army saw this, they rose up in a clamor to watch, and at that moment, a hawk from the sky attacked a kite, and it fell headlong directly in front of him, which the royal soldiers struck with spears and caught.
A7: First 5% | B7: vol1 | C7: 71 | D7: vol1_s000407 | E7: vol1_s000407_t06_9f6b39839bb4 | F7: Omen | G7: SIGNALED_VICTORY_FOR | H7: Alaungmintayagyi | I7: supported | J7: Supported by the Burmese sentence and allowed narrative context; grouping and contextually inferred participants accepted. | L7: ထိုအခါ အလောင်းမင်းတရားကြီး ဘုရားလည်း သက္ကရာဇ် တစ်ထောင့် တစ်ရာ့ လေးဆယ့် လေးခု၊ ကဆုန်လပြည့်ကျော်ရှစ်ရက် သောကြာနေ့၊ မွန်းယိမ်းနှစ်ချက်တီးကျော် နှစ်မောင်းတွင် အတန္တုအားဖြင့် တာဝတိံသာ မဟာသုဒဿနမြို့သို့ ချီတက်လာကုန်သော အသူရာစစ်သည်တို့ကို နှိပ်နင်းအံ့သောငှာ မင်္ဂလာရှိသော စိတ္တကုဋ် တံခါးမှ သိကြားထွက်စံသကဲ့သို့ အောင်တံခွန်ကို လွှားလွှားလွှင့်တော်မူ၍ သားတော်မြတ် နှစ်ပါးနှင့်တကွ ဆွေတော် မျိုးတော် ကျွန်တော်ရင်း မြင်းရည်တက် လေးဆယ့်ခြောက်ခေါင်း အစု အမှုထမ်း လက်နက်စွဲ သူရဲအပေါင်း ခြံရံလျက် မင်းတို့စံပယ်ခြင်းဖြင့် စည်တော်ရွမ်း၍ အရှေ့မျက်နှာ လက်ယာတံခါးမှ ရွှေထီးဖြန့်လျက် ထွက်တော် မူသည်ကို မွန်တို့တပ်က မြင်လျှင် သောသောထ၍ ကြည့်ကြစဉ် ကောင်းကင်အရပ်က သိမ်းငှက်တစ်ခုသည် စွန်ရဲကို တိုက်၍ ရှေ့တော်တူရူ ဦးခေါင်းငိုက်ဆိုက် ကျလာသည်ကို ရဲမက်တော်တို့ လှံနှင့်နှိပ်၍ ရလိုက်သည်။ | M7: At that time, Alaungmintayagyi Paya, in the year 1144, on the eighth day of the waning moon of Kason, a Friday, at the time just past two strokes of the afternoon, in order to suppress the Asura soldiers who were marching toward the Tavatimsa Mahasudassana city as if by analogy, raised the victory banner high as if Sakra were emerging from the auspicious Cittakuta gate, and surrounded by his two noble sons, his relatives, his kin, his loyal servants, forty-six cavalrymen, and all the armed soldiers and service personnel, with the royal drums beating in the royal manner, he emerged from the right gate on the eastern side with the golden umbrella spread; when the Mon army saw this, they rose up in a clamor to watch, and at that moment, a hawk from the sky attacked a kite, and it fell headlong directly in front of him, which the royal soldiers struck with spears and caught.
A8: First 5% | B8: vol1 | C8: 71 | D8: vol1_s000408 | E8: vol1_s000408_t01_b0fbd1f80d6b | F8: Alaungmintayagyi | G8: INTERPRETED_OMEN_AS | H8: inevitable_victory | I8: supported | J8: Supported by the Burmese sentence and allowed narrative context; grouping and contextually inferred participants accepted. | L8: ထိုနိမိတ်ကို မြင်တော်မူလျှင် စွန်နံဖြစ်သော မွန်ကို သိမ်းနံဖြစ်သော ငါမင်းတရားသည် ယခုနေ့ အောင်မြင် တော်မူမည် မချွတ်ဟု ဘတ်တော်မူပြီးမှ ငါတည်း မင်းမျိုးမင်းမြစ် မှန်သည်ဖြစ်၍ ရဟန်းရှင်လူ ပြည်သူတကာ သာသနာတော်မြတ်၏ စီးပွား၊ မယ်တော်, ခမည်းတော်, ဆွေတော် မျိုးတော်တို့၏ စီးပွား၊ သားတော်အစဉ် မြေးတော်အဆက် မြစ်တော်အညွန့် တိုင်အောင် ဆောင်တော်မူထိုက်သည် မှန်လျှင် သိကြား၊ စတုလောကပါလာ၊ သာသနာတော်မြတ်ကို စောင့်ကုန်သော သမ္မာဒေဝ နတ်မြတ်အပေါင်း ကောင်းသော ကြည့်ရှုခြင်းဖြင့် ညီညာ ရွက်ဆောင်သည်ဖြစ်၍ အလွယ်တကူ ရန်သူတော်တို့ကို လှံထင်ဆောက်ကာ ပြီးမြောက် အောင်မြင်တော်မူစေ သောဟု ရွှေကရားဖြင့် ရေစက်သွန်းတော်မူပြီးလျှင် ရေ မြေသို့ရောက်သည်နှင့် တစ်ပြိုင်နက် “အောင်ခါ ရောက်ပြီ၊ အောင်ချိန်သင့်ပြီ၊ အောင်ခါတန်ပြီ”ဟု ညွှန်းသော စကားဖြင့် အောင်သံပေးတော်မူသည်ကို မြန်မာစစ်သည် မွန်စစ်သည် အပေါင်းတို့သည် နားရင်းကြပ်ကြပ်အပ်၍ ဟစ်ကြော်ဘိကဲ့သို့ တပ်လုံး ကြားလေ၏။ | M8: Upon seeing this omen, he declared, 'I, King Alaungmintaya, who am the hawk, will undoubtedly be victorious this day over the Mon, who are the kite,' and after declaring this, he poured water from a golden ewer, saying, 'Since I am truly of royal lineage, if it is true that I am worthy to carry out the welfare of the noble religion for all monks and laypeople, the welfare of my mother, father, relatives, and kin, and the welfare of my sons, grandsons, and great-grandsons, then may Sakra, the Four Heavenly Kings, and all the noble Samma-deva spirits who guard the noble religion look upon me with favor, act in unison, and cause me to easily pierce the enemies with spears and achieve complete victory,' and as soon as the water reached the earth, he gave the signal for victory with the words, 'The time for victory has arrived, the time for victory is appropriate, the time for victory is due,' which the Burmese soldiers and all the Mon soldiers heard throughout the entire camp as if they were shouting it right into their ears.
A9: First 5% | B9: vol1 | C9: 71 | D9: vol1_s000408 | E9: vol1_s000408_t02_c56a1c317678 | F9: Alaungmintayagyi | G9: INVOKED_SUPERNATURAL_PROTECTION_OF | H9: Sakra_and_Four_Heavenly_Kings_and_Samma_deva_spirits | I9: supported | J9: Supported by the Burmese sentence and allowed narrative context; grouping and contextually inferred participants accepted. | L9: ထိုနိမိတ်ကို မြင်တော်မူလျှင် စွန်နံဖြစ်သော မွန်ကို သိမ်းနံဖြစ်သော ငါမင်းတရားသည် ယခုနေ့ အောင်မြင် တော်မူမည် မချွတ်ဟု ဘတ်တော်မူပြီးမှ ငါတည်း မင်းမျိုးမင်းမြစ် မှန်သည်ဖြစ်၍ ရဟန်းရှင်လူ ပြည်သူတကာ သာသနာတော်မြတ်၏ စီးပွား၊ မယ်တော်, ခမည်းတော်, ဆွေတော် မျိုးတော်တို့၏ စီးပွား၊ သားတော်အစဉ် မြေးတော်အဆက် မြစ်တော်အညွန့် တိုင်အောင် ဆောင်တော်မူထိုက်သည် မှန်လျှင် သိကြား၊ စတုလောကပါလာ၊ သာသနာတော်မြတ်ကို စောင့်ကုန်သော သမ္မာဒေဝ နတ်မြတ်အပေါင်း ကောင်းသော ကြည့်ရှုခြင်းဖြင့် ညီညာ ရွက်ဆောင်သည်ဖြစ်၍ အလွယ်တကူ ရန်သူတော်တို့ကို လှံထင်ဆောက်ကာ ပြီးမြောက် အောင်မြင်တော်မူစေ သောဟု ရွှေကရားဖြင့် ရေစက်သွန်းတော်မူပြီးလျှင် ရေ မြေသို့ရောက်သည်နှင့် တစ်ပြိုင်နက် “အောင်ခါ ရောက်ပြီ၊ အောင်ချိန်သင့်ပြီ၊ အောင်ခါတန်ပြီ”ဟု ညွှန်းသော စကားဖြင့် အောင်သံပေးတော်မူသည်ကို မြန်မာစစ်သည် မွန်စစ်သည် အပေါင်းတို့သည် နားရင်းကြပ်ကြပ်အပ်၍ ဟစ်ကြော်ဘိကဲ့သို့ တပ်လုံး ကြားလေ၏။ | M9: Upon seeing this omen, he declared, 'I, King Alaungmintaya, who am the hawk, will undoubtedly be victorious this day over the Mon, who are the kite,' and after declaring this, he poured water from a golden ewer, saying, 'Since I am truly of royal lineage, if it is true that I am worthy to carry out the welfare of the noble religion for all monks and laypeople, the welfare of my mother, father, relatives, and kin, and the welfare of my sons, grandsons, and great-grandsons, then may Sakra, the Four Heavenly Kings, and all the noble Samma-deva spirits who guard the noble religion look upon me with favor, act in unison, and cause me to easily pierce the enemies with spears and achieve complete victory,' and as soon as the water reached the earth, he gave the signal for victory with the words, 'The time for victory has arrived, the time for victory is appropriate, the time for victory is due,' which the Burmese soldiers and all the Mon soldiers heard throughout the entire camp as if they were shouting it right into their ears.
A10: First 5% | B10: vol1 | C10: 71 | D10: vol1_s000408 | E10: vol1_s000408_t03_d6fdde6ee5ab | F10: Alaungmintayagyi | G10: PERFORMED_RITUAL_OATH_VIA | H10: pouring_water_from_golden_ewer | I10: supported | J10: Supported by the Burmese sentence and allowed narrative context; grouping and contextually inferred participants accepted. | L10: ထိုနိမိတ်ကို မြင်တော်မူလျှင် စွန်နံဖြစ်သော မွန်ကို သိမ်းနံဖြစ်သော ငါမင်းတရားသည် ယခုနေ့ အောင်မြင် တော်မူမည် မချွတ်ဟု ဘတ်တော်မူပြီးမှ ငါတည်း မင်းမျိုးမင်းမြစ် မှန်သည်ဖြစ်၍ ရဟန်းရှင်လူ ပြည်သူတကာ သာသနာတော်မြတ်၏ စီးပွား၊ မယ်တော်, ခမည်းတော်, ဆွေတော် မျိုးတော်တို့၏ စီးပွား၊ သားတော်အစဉ် မြေးတော်အဆက် မြစ်တော်အညွန့် တိုင်အောင် ဆောင်တော်မူထိုက်သည် မှန်လျှင် သိကြား၊ စတုလောကပါလာ၊ သာသနာတော်မြတ်ကို စောင့်ကုန်သော သမ္မာဒေဝ နတ်မြတ်အပေါင်း ကောင်းသော ကြည့်ရှုခြင်းဖြင့် ညီညာ ရွက်ဆောင်သည်ဖြစ်၍ အလွယ်တကူ ရန်သူတော်တို့ကို လှံထင်ဆောက်ကာ ပြီးမြောက် အောင်မြင်တော်မူစေ သောဟု ရွှေကရားဖြင့် ရေစက်သွန်းတော်မူပြီးလျှင် ရေ မြေသို့ရောက်သည်နှင့် တစ်ပြိုင်နက် “အောင်ခါ ရောက်ပြီ၊ အောင်ချိန်သင့်ပြီ၊ အောင်ခါတန်ပြီ”ဟု ညွှန်းသော စကားဖြင့် အောင်သံပေးတော်မူသည်ကို မြန်မာစစ်သည် မွန်စစ်သည် အပေါင်းတို့သည် နားရင်းကြပ်ကြပ်အပ်၍ ဟစ်ကြော်ဘိကဲ့သို့ တပ်လုံး ကြားလေ၏။ | M10: Upon seeing this omen, he declared, 'I, King Alaungmintaya, who am the hawk, will undoubtedly be victorious this day over the Mon, who are the kite,' and after declaring this, he poured water from a golden ewer, saying, 'Since I am truly of royal lineage, if it is true that I am worthy to carry out the welfare of the noble religion for all monks and laypeople, the welfare of my mother, father, relatives, and kin, and the welfare of my sons, grandsons, and great-grandsons, then may Sakra, the Four Heavenly Kings, and all the noble Samma-deva spirits who guard the noble religion look upon me with favor, act in unison, and cause me to easily pierce the enemies with spears and achieve complete victory,' and as soon as the water reached the earth, he gave the signal for victory with the words, 'The time for victory has arrived, the time for victory is appropriate, the time for victory is due,' which the Burmese soldiers and all the Mon soldiers heard throughout the entire camp as if they were shouting it right into their ears.
A11: First 5% | B11: vol1 | C11: 71 | D11: vol1_s000408 | E11: vol1_s000408_t04_53fd29578911 | F11: Alaungmintayagyi | G11: CLAIMED_LEGITIMACY_THROUGH | H11: royal_lineage_and_Buddhist_welfare | I11: supported | J11: Supported by the Burmese sentence and allowed narrative context; grouping and contextually inferred participants accepted. | L11: ထိုနိမိတ်ကို မြင်တော်မူလျှင် စွန်နံဖြစ်သော မွန်ကို သိမ်းနံဖြစ်သော ငါမင်းတရားသည် ယခုနေ့ အောင်မြင် တော်မူမည် မချွတ်ဟု ဘတ်တော်မူပြီးမှ ငါတည်း မင်းမျိုးမင်းမြစ် မှန်သည်ဖြစ်၍ ရဟန်းရှင်လူ ပြည်သူတကာ သာသနာတော်မြတ်၏ စီးပွား၊ မယ်တော်, ခမည်းတော်, ဆွေတော် မျိုးတော်တို့၏ စီးပွား၊ သားတော်အစဉ် မြေးတော်အဆက် မြစ်တော်အညွန့် တိုင်အောင် ဆောင်တော်မူထိုက်သည် မှန်လျှင် သိကြား၊ စတုလောကပါလာ၊ သာသနာတော်မြတ်ကို စောင့်ကုန်သော သမ္မာဒေဝ နတ်မြတ်အပေါင်း ကောင်းသော ကြည့်ရှုခြင်းဖြင့် ညီညာ ရွက်ဆောင်သည်ဖြစ်၍ အလွယ်တကူ ရန်သူတော်တို့ကို လှံထင်ဆောက်ကာ ပြီးမြောက် အောင်မြင်တော်မူစေ သောဟု ရွှေကရားဖြင့် ရေစက်သွန်းတော်မူပြီးလျှင် ရေ မြေသို့ရောက်သည်နှင့် တစ်ပြိုင်နက် “အောင်ခါ ရောက်ပြီ၊ အောင်ချိန်သင့်ပြီ၊ အောင်ခါတန်ပြီ”ဟု ညွှန်းသော စကားဖြင့် အောင်သံပေးတော်မူသည်ကို မြန်မာစစ်သည် မွန်စစ်သည် အပေါင်းတို့သည် နားရင်းကြပ်ကြပ်အပ်၍ ဟစ်ကြော်ဘိကဲ့သို့ တပ်လုံး ကြားလေ၏။ | M11: Upon seeing this omen, he declared, 'I, King Alaungmintaya, who am the hawk, will undoubtedly be victorious this day over the Mon, who are the kite,' and after declaring this, he poured water from a golden ewer, saying, 'Since I am truly of royal lineage, if it is true that I am worthy to carry out the welfare of the noble religion for all monks and laypeople, the welfare of my mother, father, relatives, and kin, and the welfare of my sons, grandsons, and great-grandsons, then may Sakra, the Four Heavenly Kings, and all the noble Samma-deva spirits who guard the noble religion look upon me with favor, act in unison, and cause me to easily pierce the enemies with spears and achieve complete victory,' and as soon as the water reached the earth, he gave the signal for victory with the words, 'The time for victory has arrived, the time for victory is appropriate, the time for victory is due,' which the Burmese soldiers and all the Mon soldiers heard throughout the entire camp as if they were shouting it right into their ears.
A12: First 5% | B12: vol1 | C12: 71 | D12: vol1_s000408 | E12: vol1_s000408_t05_515c37baf5b4 | F12: Alaungmintayagyi | G12: ISSUED_COMMAND_TO | H12: Burmese_and_Mon_soldiers | I12: soft | J12: Both armies hear the king’s victory cry. The triple turns that joint audience into the recipients of a command, including the enemy. The utterance is real, but its relation to the audience is misconstructed. | K12: Alaungmintayagyi | GAVE_VICTORY_SIGNAL_HEARD_BY | Burmese and Mon soldiers | L12: ထိုနိမိတ်ကို မြင်တော်မူလျှင် စွန်နံဖြစ်သော မွန်ကို သိမ်းနံဖြစ်သော ငါမင်းတရားသည် ယခုနေ့ အောင်မြင် တော်မူမည် မချွတ်ဟု ဘတ်တော်မူပြီးမှ ငါတည်း မင်းမျိုးမင်းမြစ် မှန်သည်ဖြစ်၍ ရဟန်းရှင်လူ ပြည်သူတကာ သာသနာတော်မြတ်၏ စီးပွား၊ မယ်တော်, ခမည်းတော်, ဆွေတော် မျိုးတော်တို့၏ စီးပွား၊ သားတော်အစဉ် မြေးတော်အဆက် မြစ်တော်အညွန့် တိုင်အောင် ဆောင်တော်မူထိုက်သည် မှန်လျှင် သိကြား၊ စတုလောကပါလာ၊ သာသနာတော်မြတ်ကို စောင့်ကုန်သော သမ္မာဒေဝ နတ်မြတ်အပေါင်း ကောင်းသော ကြည့်ရှုခြင်းဖြင့် ညီညာ ရွက်ဆောင်သည်ဖြစ်၍ အလွယ်တကူ ရန်သူတော်တို့ကို လှံထင်ဆောက်ကာ ပြီးမြောက် အောင်မြင်တော်မူစေ သောဟု ရွှေကရားဖြင့် ရေစက်သွန်းတော်မူပြီးလျှင် ရေ မြေသို့ရောက်သည်နှင့် တစ်ပြိုင်နက် “အောင်ခါ ရောက်ပြီ၊ အောင်ချိန်သင့်ပြီ၊ အောင်ခါတန်ပြီ”ဟု ညွှန်းသော စကားဖြင့် အောင်သံပေးတော်မူသည်ကို မြန်မာစစ်သည် မွန်စစ်သည် အပေါင်းတို့သည် နားရင်းကြပ်ကြပ်အပ်၍ ဟစ်ကြော်ဘိကဲ့သို့ တပ်လုံး ကြားလေ၏။ | M12: Upon seeing this omen, he declared, 'I, King Alaungmintaya, who am the hawk, will undoubtedly be victorious this day over the Mon, who are the kite,' and after declaring this, he poured water from a golden ewer, saying, 'Since I am truly of royal lineage, if it is true that I am worthy to carry out the welfare of the noble religion for all monks and laypeople, the welfare of my mother, father, relatives, and kin, and the welfare of my sons, grandsons, and great-grandsons, then may Sakra, the Four Heavenly Kings, and all the noble Samma-deva spirits who guard the noble religion look upon me with favor, act in unison, and cause me to easily pierce the enemies with spears and achieve complete victory,' and as soon as the water reached the earth, he gave the signal for victory with the words, 'The time for victory has arrived, the time for victory is appropriate, the time for victory is due,' which the Burmese soldiers and all the Mon soldiers heard throughout the entire camp as if they were shouting it right into their ears.
A13: First 5% | B13: vol1 | C13: 71 | D13: vol1_s000408 | E13: vol1_s000408_t06_8c758f29b409 | F13: Burmese_and_Mon_soldiers | G13: HEARD_ROYAL_SIGNAL_OF | H13: victory | I13: supported | J13: Supported by the Burmese sentence and allowed narrative context; grouping and contextually inferred participants accepted. | L13: ထိုနိမိတ်ကို မြင်တော်မူလျှင် စွန်နံဖြစ်သော မွန်ကို သိမ်းနံဖြစ်သော ငါမင်းတရားသည် ယခုနေ့ အောင်မြင် တော်မူမည် မချွတ်ဟု ဘတ်တော်မူပြီးမှ ငါတည်း မင်းမျိုးမင်းမြစ် မှန်သည်ဖြစ်၍ ရဟန်းရှင်လူ ပြည်သူတကာ သာသနာတော်မြတ်၏ စီးပွား၊ မယ်တော်, ခမည်းတော်, ဆွေတော် မျိုးတော်တို့၏ စီးပွား၊ သားတော်အစဉ် မြေးတော်အဆက် မြစ်တော်အညွန့် တိုင်အောင် ဆောင်တော်မူထိုက်သည် မှန်လျှင် သိကြား၊ စတုလောကပါလာ၊ သာသနာတော်မြတ်ကို စောင့်ကုန်သော သမ္မာဒေဝ နတ်မြတ်အပေါင်း ကောင်းသော ကြည့်ရှုခြင်းဖြင့် ညီညာ ရွက်ဆောင်သည်ဖြစ်၍ အလွယ်တကူ ရန်သူတော်တို့ကို လှံထင်ဆောက်ကာ ပြီးမြောက် အောင်မြင်တော်မူစေ သောဟု ရွှေကရားဖြင့် ရေစက်သွန်းတော်မူပြီးလျှင် ရေ မြေသို့ရောက်သည်နှင့် တစ်ပြိုင်နက် “အောင်ခါ ရောက်ပြီ၊ အောင်ချိန်သင့်ပြီ၊ အောင်ခါတန်ပြီ”ဟု ညွှန်းသော စကားဖြင့် အောင်သံပေးတော်မူသည်ကို မြန်မာစစ်သည် မွန်စစ်သည် အပေါင်းတို့သည် နားရင်းကြပ်ကြပ်အပ်၍ ဟစ်ကြော်ဘိကဲ့သို့ တပ်လုံး ကြားလေ၏။ | M13: Upon seeing this omen, he declared, 'I, King Alaungmintaya, who am the hawk, will undoubtedly be victorious this day over the Mon, who are the kite,' and after declaring this, he poured water from a golden ewer, saying, 'Since I am truly of royal lineage, if it is true that I am worthy to carry out the welfare of the noble religion for all monks and laypeople, the welfare of my mother, father, relatives, and kin, and the welfare of my sons, grandsons, and great-grandsons, then may Sakra, the Four Heavenly Kings, and all the noble Samma-deva spirits who guard the noble religion look upon me with favor, act in unison, and cause me to easily pierce the enemies with spears and achieve complete victory,' and as soon as the water reached the earth, he gave the signal for victory with the words, 'The time for victory has arrived, the time for victory is appropriate, the time for victory is due,' which the Burmese soldiers and all the Mon soldiers heard throughout the entire camp as if they were shouting it right into their ears.
A14: First 5% | B14: vol1 | C14: 71 | D14: vol1_s000409 | E14: vol1_s000409_t01_7dd4a7d1314c | F14: Alaungmintayagyi | G14: EXERTED_ROYAL_AUTHORITY_THROUGH | H14: voice_and_charisma | I14: supported | J14: Supported by the Burmese sentence and allowed narrative context; grouping and contextually inferred participants accepted. | L14: ထိုအခါ ပမာအားဖြင့် ကေသရရာဇာ ခြင်္သေ့မင်းသည် ရွှေဂူဝမှ ခုန်ကြွစံပယ်လျက် ထွက်၍ ဟောက်မြူးသောအသံကို တောင်ယံကမ်းပါး ကျက်စားရှိကုန်သော သားအပေါင်းတို့သည် ကြောက်ခြင်းပြင်းရကား ကမ်းပါးချောက်သို့ ဦးစောက်ကျဘိ သကဲ့သို့ မွန်စစ်သည် အပေါင်းတို့သည် အလောင်းမင်းတရားကြီးဘုရား အသံတော်ကို ကြားလျှင် ဘုန်းအာဏာတော်အား သတိမတည်နိုင်၍ လက်နက်လွတ်ကျသော ဟူ၏။ | M14: At that time, it is said that just as when the lion king, the Kesararaja, leaps out from the mouth of a golden cave and roars, all the animals living on the mountain slopes are so terrified that they fall headlong into the ravines, so too, when the Mon soldiers heard the voice of Alaungmintayagyi Paya, they could not maintain their composure due to his royal power and authority, and they dropped their weapons.
A15: First 5% | B15: vol1 | C15: 71 | D15: vol1_s000409 | E15: vol1_s000409_t02_02d08094e321 | F15: Mon_soldiers | G15: SUFFERED_MORALE_COLLAPSE_FROM | H15: Alaungmintayagyi_voice | I15: supported | J15: Supported by the Burmese sentence and allowed narrative context; grouping and contextually inferred participants accepted. | L15: ထိုအခါ ပမာအားဖြင့် ကေသရရာဇာ ခြင်္သေ့မင်းသည် ရွှေဂူဝမှ ခုန်ကြွစံပယ်လျက် ထွက်၍ ဟောက်မြူးသောအသံကို တောင်ယံကမ်းပါး ကျက်စားရှိကုန်သော သားအပေါင်းတို့သည် ကြောက်ခြင်းပြင်းရကား ကမ်းပါးချောက်သို့ ဦးစောက်ကျဘိ သကဲ့သို့ မွန်စစ်သည် အပေါင်းတို့သည် အလောင်းမင်းတရားကြီးဘုရား အသံတော်ကို ကြားလျှင် ဘုန်းအာဏာတော်အား သတိမတည်နိုင်၍ လက်နက်လွတ်ကျသော ဟူ၏။ | M15: At that time, it is said that just as when the lion king, the Kesararaja, leaps out from the mouth of a golden cave and roars, all the animals living on the mountain slopes are so terrified that they fall headlong into the ravines, so too, when the Mon soldiers heard the voice of Alaungmintayagyi Paya, they could not maintain their composure due to his royal power and authority, and they dropped their weapons.
A16: First 5% | B16: vol1 | C16: 71 | D16: vol1_s000409 | E16: vol1_s000409_t03_60475c497770 | F16: Mon_soldiers | G16: ABANDONED_WEAPONS_DUE_TO | H16: royal_power | I16: supported | J16: Supported by the Burmese sentence and allowed narrative context; grouping and contextually inferred participants accepted. | L16: ထိုအခါ ပမာအားဖြင့် ကေသရရာဇာ ခြင်္သေ့မင်းသည် ရွှေဂူဝမှ ခုန်ကြွစံပယ်လျက် ထွက်၍ ဟောက်မြူးသောအသံကို တောင်ယံကမ်းပါး ကျက်စားရှိကုန်သော သားအပေါင်းတို့သည် ကြောက်ခြင်းပြင်းရကား ကမ်းပါးချောက်သို့ ဦးစောက်ကျဘိ သကဲ့သို့ မွန်စစ်သည် အပေါင်းတို့သည် အလောင်းမင်းတရားကြီးဘုရား အသံတော်ကို ကြားလျှင် ဘုန်းအာဏာတော်အား သတိမတည်နိုင်၍ လက်နက်လွတ်ကျသော ဟူ၏။ | M16: At that time, it is said that just as when the lion king, the Kesararaja, leaps out from the mouth of a golden cave and roars, all the animals living on the mountain slopes are so terrified that they fall headlong into the ravines, so too, when the Mon soldiers heard the voice of Alaungmintayagyi Paya, they could not maintain their composure due to his royal power and authority, and they dropped their weapons.
A17: First 5% | B17: vol1 | C17: 71 | D17: vol1_s000410 | E17: vol1_s000410_t01_6fb674c9e392 | F17: Royal_army | G17: EXECUTED_COMMAND_OF | H17: Alaungmintayagyi | I17: supported | J17: Supported by the Burmese sentence and allowed narrative context; grouping and contextually inferred participants accepted. | L17: " ယင်းသို့ စင်တွင် တပ်မတော်မှ အောင်စည် အောင်မောင်း သောင်းသောင်းသောသော တီးမှုတ်စေလျက် အမှတ်ပေးတော်မူလျှင် လေးဆယ့်ငါးတပ် စွဲမှတ်ရှိနေကုန်သော မြင်းစီးသူရဲ၊ သေနတ်စွဲသူရဲ၊ လေးစွဲသူရဲ၊ ရထားစွဲသူရဲ၊ တင်ကျည်းစွဲ သူရဲတို့လည်း တစ်ပြိုင်နက် ကြော်ငြာလျက် အဆုတ်အဆိုင်းမရှိ ချွံချွံရွပ်ရွပ် ထိုးခုတ်ပစ်ခတ်ကြသည်ကို မွန်တို့လည်း မဆုတ်မနစ် ကြိုး၍ခံသည်၊ မနည်းကြာ တစ်ဦးကိုတစ်ဦး မတိုးမဝှေ့ နိုင်၊ အထွေးထွေးရှိစဉ် အလောင်း မင်းတရားကြီးဘုရား ကိုယ်တော်တိုင် ကွပ်သည်ကို ရဲမက်တော်တို့မြင်လျှင် အသက်ကို ပန်းတစ်ပွင့် အနှိုင်းမမှတ် စွန့်စား ထိုးခုတ် ပစ်ခတ်ကြသောကြောင့် မွန်တို့ အရှအန အသေအပျောက် များသည်နှင့် မနည်းကြာအမ်း၍ ရှိနေစဉ် တပ်မတော်နှင့်တကွ တောင်ဘိ၏သို့ တစ်ဟုန်တည်း တိုက်တော်မူလျှင် မွန်တို့ မခံနိုင်၍ အဆီးအတားမရှိ ပျက်လေ၏။ | M17: In this way, when the royal army gave the signal by beating the victory drums and gongs loudly, the forty-five units of cavalrymen, musketeers, archers, charioteers, and spearmen all at once shouted and charged forward without hesitation, stabbing and shooting fiercely; the Mon also resisted with unyielding effort, and for a while, they could not push or shove one another, and while they were in this state of entanglement, the royal soldiers saw Alaungmintayagyi Paya himself directing the battle, and because they fought, stabbed, and shot with such abandon, regarding their lives as no more than a flower, the Mon suffered many casualties and deaths, and while they were wavering for a while, he attacked with the royal army in one swift rush toward the south, and the Mon could not withstand it and were defeated without obstruction.
A18: First 5% | B18: vol1 | C18: 71 | D18: vol1_s000410 | E18: vol1_s000410_t02_ef2633dfdf11 | F18: Alaungmintayagyi | G18: DIRECTED_BATTLE_PERSONALLY | H18: royal_army | I18: supported | J18: Supported by the Burmese sentence and allowed narrative context; grouping and contextually inferred participants accepted. | L18: " ယင်းသို့ စင်တွင် တပ်မတော်မှ အောင်စည် အောင်မောင်း သောင်းသောင်းသောသော တီးမှုတ်စေလျက် အမှတ်ပေးတော်မူလျှင် လေးဆယ့်ငါးတပ် စွဲမှတ်ရှိနေကုန်သော မြင်းစီးသူရဲ၊ သေနတ်စွဲသူရဲ၊ လေးစွဲသူရဲ၊ ရထားစွဲသူရဲ၊ တင်ကျည်းစွဲ သူရဲတို့လည်း တစ်ပြိုင်နက် ကြော်ငြာလျက် အဆုတ်အဆိုင်းမရှိ ချွံချွံရွပ်ရွပ် ထိုးခုတ်ပစ်ခတ်ကြသည်ကို မွန်တို့လည်း မဆုတ်မနစ် ကြိုး၍ခံသည်၊ မနည်းကြာ တစ်ဦးကိုတစ်ဦး မတိုးမဝှေ့ နိုင်၊ အထွေးထွေးရှိစဉ် အလောင်း မင်းတရားကြီးဘုရား ကိုယ်တော်တိုင် ကွပ်သည်ကို ရဲမက်တော်တို့မြင်လျှင် အသက်ကို ပန်းတစ်ပွင့် အနှိုင်းမမှတ် စွန့်စား ထိုးခုတ် ပစ်ခတ်ကြသောကြောင့် မွန်တို့ အရှအန အသေအပျောက် များသည်နှင့် မနည်းကြာအမ်း၍ ရှိနေစဉ် တပ်မတော်နှင့်တကွ တောင်ဘိ၏သို့ တစ်ဟုန်တည်း တိုက်တော်မူလျှင် မွန်တို့ မခံနိုင်၍ အဆီးအတားမရှိ ပျက်လေ၏။ | M18: In this way, when the royal army gave the signal by beating the victory drums and gongs loudly, the forty-five units of cavalrymen, musketeers, archers, charioteers, and spearmen all at once shouted and charged forward without hesitation, stabbing and shooting fiercely; the Mon also resisted with unyielding effort, and for a while, they could not push or shove one another, and while they were in this state of entanglement, the royal soldiers saw Alaungmintayagyi Paya himself directing the battle, and because they fought, stabbed, and shot with such abandon, regarding their lives as no more than a flower, the Mon suffered many casualties and deaths, and while they were wavering for a while, he attacked with the royal army in one swift rush toward the south, and the Mon could not withstand it and were defeated without obstruction.
A19: First 5% | B19: vol1 | C19: 71 | D19: vol1_s000410 | E19: vol1_s000410_t03_46bb5d1bcdce | F19: Mon_forces | G19: RESISTED_MILITARY_ASSAULT_OF | H19: royal_army | I19: supported | J19: Supported by the Burmese sentence and allowed narrative context; grouping and contextually inferred participants accepted. | L19: " ယင်းသို့ စင်တွင် တပ်မတော်မှ အောင်စည် အောင်မောင်း သောင်းသောင်းသောသော တီးမှုတ်စေလျက် အမှတ်ပေးတော်မူလျှင် လေးဆယ့်ငါးတပ် စွဲမှတ်ရှိနေကုန်သော မြင်းစီးသူရဲ၊ သေနတ်စွဲသူရဲ၊ လေးစွဲသူရဲ၊ ရထားစွဲသူရဲ၊ တင်ကျည်းစွဲ သူရဲတို့လည်း တစ်ပြိုင်နက် ကြော်ငြာလျက် အဆုတ်အဆိုင်းမရှိ ချွံချွံရွပ်ရွပ် ထိုးခုတ်ပစ်ခတ်ကြသည်ကို မွန်တို့လည်း မဆုတ်မနစ် ကြိုး၍ခံသည်၊ မနည်းကြာ တစ်ဦးကိုတစ်ဦး မတိုးမဝှေ့ နိုင်၊ အထွေးထွေးရှိစဉ် အလောင်း မင်းတရားကြီးဘုရား ကိုယ်တော်တိုင် ကွပ်သည်ကို ရဲမက်တော်တို့မြင်လျှင် အသက်ကို ပန်းတစ်ပွင့် အနှိုင်းမမှတ် စွန့်စား ထိုးခုတ် ပစ်ခတ်ကြသောကြောင့် မွန်တို့ အရှအန အသေအပျောက် များသည်နှင့် မနည်းကြာအမ်း၍ ရှိနေစဉ် တပ်မတော်နှင့်တကွ တောင်ဘိ၏သို့ တစ်ဟုန်တည်း တိုက်တော်မူလျှင် မွန်တို့ မခံနိုင်၍ အဆီးအတားမရှိ ပျက်လေ၏။ | M19: In this way, when the royal army gave the signal by beating the victory drums and gongs loudly, the forty-five units of cavalrymen, musketeers, archers, charioteers, and spearmen all at once shouted and charged forward without hesitation, stabbing and shooting fiercely; the Mon also resisted with unyielding effort, and for a while, they could not push or shove one another, and while they were in this state of entanglement, the royal soldiers saw Alaungmintayagyi Paya himself directing the battle, and because they fought, stabbed, and shot with such abandon, regarding their lives as no more than a flower, the Mon suffered many casualties and deaths, and while they were wavering for a while, he attacked with the royal army in one swift rush toward the south, and the Mon could not withstand it and were defeated without obstruction.
A20: First 5% | B20: vol1 | C20: 71 | D20: vol1_s000410 | E20: vol1_s000410_t04_3fe015232093 | F20: Mon_forces | G20: SUFFERED_DEFEAT_BY | H20: royal_army | I20: supported | J20: Supported by the Burmese sentence and allowed narrative context; grouping and contextually inferred participants accepted. | L20: " ယင်းသို့ စင်တွင် တပ်မတော်မှ အောင်စည် အောင်မောင်း သောင်းသောင်းသောသော တီးမှုတ်စေလျက် အမှတ်ပေးတော်မူလျှင် လေးဆယ့်ငါးတပ် စွဲမှတ်ရှိနေကုန်သော မြင်းစီးသူရဲ၊ သေနတ်စွဲသူရဲ၊ လေးစွဲသူရဲ၊ ရထားစွဲသူရဲ၊ တင်ကျည်းစွဲ သူရဲတို့လည်း တစ်ပြိုင်နက် ကြော်ငြာလျက် အဆုတ်အဆိုင်းမရှိ ချွံချွံရွပ်ရွပ် ထိုးခုတ်ပစ်ခတ်ကြသည်ကို မွန်တို့လည်း မဆုတ်မနစ် ကြိုး၍ခံသည်၊ မနည်းကြာ တစ်ဦးကိုတစ်ဦး မတိုးမဝှေ့ နိုင်၊ အထွေးထွေးရှိစဉ် အလောင်း မင်းတရားကြီးဘုရား ကိုယ်တော်တိုင် ကွပ်သည်ကို ရဲမက်တော်တို့မြင်လျှင် အသက်ကို ပန်းတစ်ပွင့် အနှိုင်းမမှတ် စွန့်စား ထိုးခုတ် ပစ်ခတ်ကြသောကြောင့် မွန်တို့ အရှအန အသေအပျောက် များသည်နှင့် မနည်းကြာအမ်း၍ ရှိနေစဉ် တပ်မတော်နှင့်တကွ တောင်ဘိ၏သို့ တစ်ဟုန်တည်း တိုက်တော်မူလျှင် မွန်တို့ မခံနိုင်၍ အဆီးအတားမရှိ ပျက်လေ၏။ | M20: In this way, when the royal army gave the signal by beating the victory drums and gongs loudly, the forty-five units of cavalrymen, musketeers, archers, charioteers, and spearmen all at once shouted and charged forward without hesitation, stabbing and shooting fiercely; the Mon also resisted with unyielding effort, and for a while, they could not push or shove one another, and while they were in this state of entanglement, the royal soldiers saw Alaungmintayagyi Paya himself directing the battle, and because they fought, stabbed, and shot with such abandon, regarding their lives as no more than a flower, the Mon suffered many casualties and deaths, and while they were wavering for a while, he attacked with the royal army in one swift rush toward the south, and the Mon could not withstand it and were defeated without obstruction.
A21: First 5% | B21: vol1 | C21: 71 | D21: vol1_s000410 | E21: vol1_s000410_t05_0fefbe13d092 | F21: Royal_soldiers | G21: DEMONSTRATED_LOYALTY_THROUGH | H21: self_sacrifice | I21: supported | J21: Supported by the Burmese sentence and allowed narrative context; grouping and contextually inferred participants accepted. | L21: " ယင်းသို့ စင်တွင် တပ်မတော်မှ အောင်စည် အောင်မောင်း သောင်းသောင်းသောသော တီးမှုတ်စေလျက် အမှတ်ပေးတော်မူလျှင် လေးဆယ့်ငါးတပ် စွဲမှတ်ရှိနေကုန်သော မြင်းစီးသူရဲ၊ သေနတ်စွဲသူရဲ၊ လေးစွဲသူရဲ၊ ရထားစွဲသူရဲ၊ တင်ကျည်းစွဲ သူရဲတို့လည်း တစ်ပြိုင်နက် ကြော်ငြာလျက် အဆုတ်အဆိုင်းမရှိ ချွံချွံရွပ်ရွပ် ထိုးခုတ်ပစ်ခတ်ကြသည်ကို မွန်တို့လည်း မဆုတ်မနစ် ကြိုး၍ခံသည်၊ မနည်းကြာ တစ်ဦးကိုတစ်ဦး မတိုးမဝှေ့ နိုင်၊ အထွေးထွေးရှိစဉ် အလောင်း မင်းတရားကြီးဘုရား ကိုယ်တော်တိုင် ကွပ်သည်ကို ရဲမက်တော်တို့မြင်လျှင် အသက်ကို ပန်းတစ်ပွင့် အနှိုင်းမမှတ် စွန့်စား ထိုးခုတ် ပစ်ခတ်ကြသောကြောင့် မွန်တို့ အရှအန အသေအပျောက် များသည်နှင့် မနည်းကြာအမ်း၍ ရှိနေစဉ် တပ်မတော်နှင့်တကွ တောင်ဘိ၏သို့ တစ်ဟုန်တည်း တိုက်တော်မူလျှင် မွန်တို့ မခံနိုင်၍ အဆီးအတားမရှိ ပျက်လေ၏။ | M21: In this way, when the royal army gave the signal by beating the victory drums and gongs loudly, the forty-five units of cavalrymen, musketeers, archers, charioteers, and spearmen all at once shouted and charged forward without hesitation, stabbing and shooting fiercely; the Mon also resisted with unyielding effort, and for a while, they could not push or shove one another, and while they were in this state of entanglement, the royal soldiers saw Alaungmintayagyi Paya himself directing the battle, and because they fought, stabbed, and shot with such abandon, regarding their lives as no more than a flower, the Mon suffered many casualties and deaths, and while they were wavering for a while, he attacked with the royal army in one swift rush toward the south, and the Mon could not withstand it and were defeated without obstruction.
A22: First 5% | B22: vol1 | C22: 71 | D22: vol1_s000411 | E22: vol1_s000411_t01_7937cc94dec9 | F22: Mon_main_army | G22: SUFFERED_COLLAPSE_OF | H22: defensive_structure | I22: supported | J22: Supported by the Burmese sentence and allowed narrative context; grouping and contextually inferred participants accepted. | L22: အရှေ့မျက်နှာက မွန်တို့ တပ်မ ပျက်လျှင် တောင်မျက်နှာ၊ အနောက်မျက်နှာ၊ မြောက်မျက်နှာ၊ ရံတပ်အလုံးလည်း ပျက်ပြန်လေ၏။ | M22: When the Mon main army on the eastern side was defeated, the southern, western, and northern sides, and all the supporting units, were also defeated.
A23: First 5% | B23: vol1 | C23: 71 | D23: vol1_s000411 | E23: vol1_s000411_t02_d89bf0092878 | F23: Mon_supporting_units | G23: SUFFERED_COLLAPSE_OF | H23: defensive_structure | I23: supported | J23: Supported by the Burmese sentence and allowed narrative context; grouping and contextually inferred participants accepted. | L23: အရှေ့မျက်နှာက မွန်တို့ တပ်မ ပျက်လျှင် တောင်မျက်နှာ၊ အနောက်မျက်နှာ၊ မြောက်မျက်နှာ၊ ရံတပ်အလုံးလည်း ပျက်ပြန်လေ၏။ | M23: When the Mon main army on the eastern side was defeated, the southern, western, and northern sides, and all the supporting units, were also defeated.
A24: First 5% | B24: vol1 | C24: 71 | D24: vol1_s000412 | E24: vol1_s000412_t01_836e01a281d6 | F24: Northern_wind | G24: AIDED_MILITARY_PURSUIT_OF | H24: royal_soldiers | I24: supported | J24: Supported by the Burmese sentence and allowed narrative context; grouping and contextually inferred participants accepted. | L24: ယင်းသောအခါ ကဆုန် နွေလ ဖြစ်လျက် မြောက်လေ ပြင်းစွာလာလတ်၍ မြူမှုန်ခြောင်းခြောင်း တောင်သို့ဘိကာ မွန်တို့ ဆုတ်ခွာသည်ကို ရဲမက်တော်တို့ လိုက်ထပ်ထိုးခုတ် ပစ်ခတ်လျှင် မွန်စစ်သည်တို့ ခါးဝတ်မဆည်း စစ်ကြီး ထောင်းထောင်းပျက်၍ ကိုယ်လွတ် ဆုတ်ခွာရလေ၏။ | M24: At that time, it being the summer month of Kason, a strong north wind blew, and as the Mon retreated toward the south amidst clouds of dust, the royal soldiers pursued them, stabbing and shooting, so the Mon soldiers, unable to even fasten their waistcloths, suffered a total collapse of their great army and had to retreat to save their own lives.
... A31: First 5% | B31: vol1 | C31: 77 | D31: vol1_s000476 | E31: vol1_s000476_t02_0709fa67e2f8 | F31: Musopo King | G31: MOBILIZED_MILITARY_FORCE | H31: 2000-3000 soldiers | I31: supported | J31: Supported by the Burmese sentence and allowed narrative context; grouping and contextually inferred participants accepted. | L31: ယင်းသောအခါ အဝဗိုလ်မှူး ငွေခွန်ဝန်က မူဆိုးပိုမင်းသည် ထန်းလုံးတပ်ကို သံမြို့မှတ်၍ လူနှစ်ထောင် သုံးထောင်နှင့် အခိုင်နေလေသည်မှာ မြောက်ဘက်တစ်လွှား ငါးစို့တစ်ခွင်၊ မြို့ကျေးရွာများကို သိမ်းရုံးပြီးလျှင် ခင်ဦးစား လက်ယာပျံချီကို မြောက်ဘက် မျက်နှာက ရံစေမည်၊ အဲနရဲ၊ အဲကန်ကောင်းတို့ကိုလည်း ကျောက်မြောင်းတိုင် မြို့ ရွာများကို သိမ်းယူဆန်တက်၍ အရှေ့မျက်နှာက ရံစေမည်။ | M31: At that time, the Ava commander, the Ngwekwanwun, stated that the Musopo King [the Mon King] had designated the Thanlon fort as a fortified city and was holding it firmly with two or three thousand men, and that after seizing the towns and villages in the Ngasint region across the north, he would have Khin-U-sa Let-ya-pyanchi surround it from the northern front, and would have Aenarae and Aekankaung seize the Kyaukmyaung-taing towns and villages and march up to surround it from the eastern front.
A32: First 5% | B32: vol1 | C32: 77 | D32: vol1_s000476 | E32: vol1_s000476_t03_e18c108df2bc | F32: Musopo King | G32: APPOINTED_COMMANDER | H32: Khin-U-sa Let-ya-pyanchi | I32: hard | J32: The speaking commander is the Ava Mon commander Ngwekhunwun, introduced by အဝဗိုလ်မှူး ငွေခွန်ဝန်က. The Moksobo ruler is the target of the encirclement, not the issuer of these assignments. | K32: Ngwekhunwun | ASSIGNED_NORTHERN_ENCIRCLEMENT_TO | Khin-U-sa Let-ya-pyanchi | L32: ယင်းသောအခါ အဝဗိုလ်မှူး ငွေခွန်ဝန်က မူဆိုးပိုမင်းသည် ထန်းလုံးတပ်ကို သံမြို့မှတ်၍ လူနှစ်ထောင် သုံးထောင်နှင့် အခိုင်နေလေသည်မှာ မြောက်ဘက်တစ်လွှား ငါးစို့တစ်ခွင်၊ မြို့ကျေးရွာများကို သိမ်းရုံးပြီးလျှင် ခင်ဦးစား လက်ယာပျံချီကို မြောက်ဘက် မျက်နှာက ရံစေမည်၊ အဲနရဲ၊ အဲကန်ကောင်းတို့ကိုလည်း ကျောက်မြောင်းတိုင် မြို့ ရွာများကို သိမ်းယူဆန်တက်၍ အရှေ့မျက်နှာက ရံစေမည်။ | M32: At that time, the Ava commander, the Ngwekwanwun, stated that the Musopo King [the Mon King] had designated the Thanlon fort as a fortified city and was holding it firmly with two or three thousand men, and that after seizing the towns and villages in the Ngasint region across the north, he would have Khin-U-sa Let-ya-pyanchi surround it from the northern front, and would have Aenarae and Aekankaung seize the Kyaukmyaung-taing towns and villages and march up to surround it from the eastern front.
A33: First 5% | B33: vol1 | C33: 77 | D33: vol1_s000476 | E33: vol1_s000476_t04_fd98cf6593fe | F33: Musopo King | G33: APPOINTED_COMMANDER | H33: Aenarae and Aekankaung | I33: hard | J33: The speaking commander is the Ava Mon commander Ngwekhunwun, introduced by အဝဗိုလ်မှူး ငွေခွန်ဝန်က. The Moksobo ruler is the target of the encirclement, not the issuer of these assignments. | K33: Ngwekhunwun | ASSIGNED_EASTERN_ENCIRCLEMENT_TO | Aenarae and Aekankaung | L33: ယင်းသောအခါ အဝဗိုလ်မှူး ငွေခွန်ဝန်က မူဆိုးပိုမင်းသည် ထန်းလုံးတပ်ကို သံမြို့မှတ်၍ လူနှစ်ထောင် သုံးထောင်နှင့် အခိုင်နေလေသည်မှာ မြောက်ဘက်တစ်လွှား ငါးစို့တစ်ခွင်၊ မြို့ကျေးရွာများကို သိမ်းရုံးပြီးလျှင် ခင်ဦးစား လက်ယာပျံချီကို မြောက်ဘက် မျက်နှာက ရံစေမည်၊ အဲနရဲ၊ အဲကန်ကောင်းတို့ကိုလည်း ကျောက်မြောင်းတိုင် မြို့ ရွာများကို သိမ်းယူဆန်တက်၍ အရှေ့မျက်နှာက ရံစေမည်။ | M33: At that time, the Ava commander, the Ngwekwanwun, stated that the Musopo King [the Mon King] had designated the Thanlon fort as a fortified city and was holding it firmly with two or three thousand men, and that after seizing the towns and villages in the Ngasint region across the north, he would have Khin-U-sa Let-ya-pyanchi surround it from the northern front, and would have Aenarae and Aekankaung seize the Kyaukmyaung-taing towns and villages and march up to surround it from the eastern front.
A34: First 5% | B34: vol1 | C34: 77 | D34: vol1_s000477 | E34: vol1_s000477_t01_9bc0ee6b5563 | F34: Musopo King | G34: APPOINTED_COMMANDER | H34: Samainzeipbyae, Samainlut, Samainthanlaik, Ye-khaung-san-kyaw | I34: hard | J34: The speaking commander is the Ava Mon commander Ngwekhunwun, introduced by အဝဗိုလ်မှူး ငွေခွန်ဝန်က. The Moksobo ruler is the target of the encirclement, not the issuer of these assignments. | K34: Ngwekhunwun | ASSIGNED_WESTERN_ENCIRCLEMENT_TO | the four Mon commanders | L34: သမိန်ဇိပ်ဗြဲ၊ သမိန်လွတ်၊ သမိန်သံလိုက်၊ ရဲခေါင်စံကျော်တို့ကိုလည်း မူးမြစ်ကြောင်း အနောက်တစ်ပြင် မြို့ရွာများကို သိမ်းယူ၍ အနောက် မျက်နှာက ရံစေမည်၊ ငါလည်း ပိုက်သီဟ၊ ပိုက်ကမြင်းတို့နှင့် စစ်ကိုင်းကြောင်း ချီတက်၍ တောင်မျက်နှာက ရံမည်၊ သည်ကဲ့သို့ လေးကြောင်း လေးမျက်နှာ တက်၍ စစ်အားကြီး လုပ်ကြံရလျှင် မုဆိုးပိုတပ်သည် ငှက်မူ၍ ပျံထွက်နိုင်မည်လောဟု ကြုံးဝါးပြီးလျှင် သက္ကရာဇ် (၁၁၁၄) တစ်ထောင့်တစ်ရာ တစ်ဆယ့်လေးခု၊ သီတင်းကျွတ်လ တွင် သမိန်ဇိပ်ဗြဲ တစ်တပ်၊ သမိန်လွတ် တစ်တပ်၊ သမိန်သံလိုက် တစ်တပ်၊ ရဲခေါင်စံကျော် တစ်တပ်၊ သည် လေးတပ်တွင် မြင်းသုံးရာ၊ စစ်သည်သူရဲနှစ်ထောင့်ငါးရာ၊ မူးမြစ်ကြောင်း ချီနှင့်ရလေ၏။ | M34: He also stated that he would have Samainzeipbyae, Samainlut, Samainthanlaik, and Ye-khaung-san-kyaw seize the towns and villages on the western side of the Mu River and surround it from the western front, and that he himself would march along the Sagaing route with Paik-thiha and Paik-kamyin and surround it from the southern front; after boasting, 'If we attack with such great military force, advancing from four directions and four fronts, will the Musopo fort be able to fly away like a bird?', in the month of Thadingyut, in the year 1114, he sent one unit of Samainzeipbyae, one unit of Samainlut, one unit of Samainthanlaik, and one unit of Ye-khaung-san-kyaw—these four units, consisting of three hundred horses and two thousand five hundred soldiers—to march along the Mu River.
A35: First 5% | B35: vol1 | C35: 77 | D35: vol1_s000477 | E35: vol1_s000477_t02_8a4279ee1476 | F35: Musopo King | G35: PLANNED_ENCIRCLEMENT | H35: Nyaung-hla | I35: hard | J35: The Mon commander plans to surround Moksobo. This triple substitutes the Moksobo king as planner and Nyaunghla as the intended target. Nyaunghla is the later Mon staging camp, not the target named in this plan. | K35: Ngwekhunwun | PLANNED_ENCIRCLEMENT_OF | Moksobo | L35: သမိန်ဇိပ်ဗြဲ၊ သမိန်လွတ်၊ သမိန်သံလိုက်၊ ရဲခေါင်စံကျော်တို့ကိုလည်း မူးမြစ်ကြောင်း အနောက်တစ်ပြင် မြို့ရွာများကို သိမ်းယူ၍ အနောက် မျက်နှာက ရံစေမည်၊ ငါလည်း ပိုက်သီဟ၊ ပိုက်ကမြင်းတို့နှင့် စစ်ကိုင်းကြောင်း ချီတက်၍ တောင်မျက်နှာက ရံမည်၊ သည်ကဲ့သို့ လေးကြောင်း လေးမျက်နှာ တက်၍ စစ်အားကြီး လုပ်ကြံရလျှင် မုဆိုးပိုတပ်သည် ငှက်မူ၍ ပျံထွက်နိုင်မည်လောဟု ကြုံးဝါးပြီးလျှင် သက္ကရာဇ် (၁၁၁၄) တစ်ထောင့်တစ်ရာ တစ်ဆယ့်လေးခု၊ သီတင်းကျွတ်လ တွင် သမိန်ဇိပ်ဗြဲ တစ်တပ်၊ သမိန်လွတ် တစ်တပ်၊ သမိန်သံလိုက် တစ်တပ်၊ ရဲခေါင်စံကျော် တစ်တပ်၊ သည် လေးတပ်တွင် မြင်းသုံးရာ၊ စစ်သည်သူရဲနှစ်ထောင့်ငါးရာ၊ မူးမြစ်ကြောင်း ချီနှင့်ရလေ၏။ | M35: He also stated that he would have Samainzeipbyae, Samainlut, Samainthanlaik, and Ye-khaung-san-kyaw seize the towns and villages on the western side of the Mu River and surround it from the western front, and that he himself would march along the Sagaing route with Paik-thiha and Paik-kamyin and surround it from the southern front; after boasting, 'If we attack with such great military force, advancing from four directions and four fronts, will the Musopo fort be able to fly away like a bird?', in the month of Thadingyut, in the year 1114, he sent one unit of Samainzeipbyae, one unit of Samainlut, one unit of Samainthanlaik, and one unit of Ye-khaung-san-kyaw—these four units, consisting of three hundred horses and two thousand five hundred soldiers—to march along the Mu River.
A36: First 5% | B36: vol1 | C36: 77 | D36: vol1_s000477 | E36: vol1_s000477_t03_25771c827e6a | F36: Musopo King | G36: MOBILIZED_MILITARY_FORCE | H36: 300 horses and 2500 soldiers | I36: hard | J36: The 300 horses and 2,500 soldiers belong to the four advancing Mon battalions, not to the Moksobo king’s force. | K36: Ngwekhunwun / four Mon commanders | DISPATCHED | 300 horses and 2500 soldiers | L36: သမိန်ဇိပ်ဗြဲ၊ သမိန်လွတ်၊ သမိန်သံလိုက်၊ ရဲခေါင်စံကျော်တို့ကိုလည်း မူးမြစ်ကြောင်း အနောက်တစ်ပြင် မြို့ရွာများကို သိမ်းယူ၍ အနောက် မျက်နှာက ရံစေမည်၊ ငါလည်း ပိုက်သီဟ၊ ပိုက်ကမြင်းတို့နှင့် စစ်ကိုင်းကြောင်း ချီတက်၍ တောင်မျက်နှာက ရံမည်၊ သည်ကဲ့သို့ လေးကြောင်း လေးမျက်နှာ တက်၍ စစ်အားကြီး လုပ်ကြံရလျှင် မုဆိုးပိုတပ်သည် ငှက်မူ၍ ပျံထွက်နိုင်မည်လောဟု ကြုံးဝါးပြီးလျှင် သက္ကရာဇ် (၁၁၁၄) တစ်ထောင့်တစ်ရာ တစ်ဆယ့်လေးခု၊ သီတင်းကျွတ်လ တွင် သမိန်ဇိပ်ဗြဲ တစ်တပ်၊ သမိန်လွတ် တစ်တပ်၊ သမိန်သံလိုက် တစ်တပ်၊ ရဲခေါင်စံကျော် တစ်တပ်၊ သည် လေးတပ်တွင် မြင်းသုံးရာ၊ စစ်သည်သူရဲနှစ်ထောင့်ငါးရာ၊ မူးမြစ်ကြောင်း ချီနှင့်ရလေ၏။ | M36: He also stated that he would have Samainzeipbyae, Samainlut, Samainthanlaik, and Ye-khaung-san-kyaw seize the towns and villages on the western side of the Mu River and surround it from the western front, and that he himself would march along the Sagaing route with Paik-thiha and Paik-kamyin and surround it from the southern front; after boasting, 'If we attack with such great military force, advancing from four directions and four fronts, will the Musopo fort be able to fly away like a bird?', in the month of Thadingyut, in the year 1114, he sent one unit of Samainzeipbyae, one unit of Samainlut, one unit of Samainthanlaik, and one unit of Ye-khaung-san-kyaw—these four units, consisting of three hundred horses and two thousand five hundred soldiers—to march along the Mu River.
A37: First 5% | B37: vol1 | C37: 77 | D37: vol1_s000478 | E37: vol1_s000478_t01_5ee6ca8a38c6 | F37: Aenarae and Aekankaung | G37: MARCHED_TO | H37: Kyaukmyaung | I37: supported | J37: Supported by the Burmese sentence and allowed narrative context; grouping and contextually inferred participants accepted. | L37: အဲနရဲ၊ အဲကန်ကောင်းတို့ လည်း ဧရာဝတီမြစ်ကြောင်း ကျောက်မြောင်းရောက် ချီရလေသည်။ | M37: Aenarae and Aekankaung also marched along the Irrawaddy River route to reach Kyaukmyaung.
A38: First 5% | B38: vol1 | C38: 77 | D38: vol1_s000479 | E38: vol1_s000479_t01_94ee31f83371 | F38: Musopo King | G38: APPOINTED_COMMANDER | H38: Khin-U-sa Let-ya-pyanchi | I38: hard | J38: The speaking commander is the Ava Mon commander Ngwekhunwun, introduced by အဝဗိုလ်မှူး ငွေခွန်ဝန်က. The Moksobo ruler is the target of the encirclement, not the issuer of these assignments. The ongoing passage describes Mon deployments. | K38: Ngwekhunwun | DISPATCHED_MON_COMMANDERS_TO | Khin-U-sa Let-ya-pyanchi | L38: ခင်ဦးစား လက်ယာပျံချီသို့လည်း မြောက်ဘက် တစ်လွှား ငါးစို့တစ်ခွင် သိမ်းရုံးစည်းကြပ်ရမည်ဟု မွန်တပ်မှူးတို့ကို ခန့်ထားစေလွှတ်သည်။ | M38: He also appointed and sent Mon commanders to Khin-U-sa Let-ya-pyanchi to seize and organize the Ngasint region across the north.
A39: First 5% | B39: vol1 | C39: 77 | D39: vol1_s000479 | E39: vol1_s000479_t02_1407a7ea8054 | F39: Khin-U-sa Let-ya-pyanchi | G39: TASKED_WITH_CONTROLLING | H39: Ngasint region | I39: supported | J39: Supported by the Burmese sentence and allowed narrative context; grouping and contextually inferred participants accepted. | L39: ခင်ဦးစား လက်ယာပျံချီသို့လည်း မြောက်ဘက် တစ်လွှား ငါးစို့တစ်ခွင် သိမ်းရုံးစည်းကြပ်ရမည်ဟု မွန်တပ်မှူးတို့ကို ခန့်ထားစေလွှတ်သည်။ | M39: He also appointed and sent Mon commanders to Khin-U-sa Let-ya-pyanchi to seize and organize the Ngasint region across the north.
A40: First 5% | B40: vol1 | C40: 77 | D40: vol1_s000480 | E40: vol1_s000480_t01_70af7dca3c1d | F40: Alaungpaya | G40: RECEIVED_INTELLIGENCE_ON | H40: Mon progress at Nyaung-hla | I40: supported | J40: Supported by the Burmese sentence and allowed narrative context; grouping and contextually inferred participants accepted. | L40: ယင်းသောအခါ အနောက်ဘက် မူးကြောင်း အလျင်ချီနှင့်ရသည့် လေးဗိုလ်လေးတပ်တို့ ညောင်လှအရပ်သို့ ရောက်ကြောင်းကို အလောင်းမင်းတရားကြီးဘုရား ကြားတော်မူသော်လည်း ရွာသစ်ကြီးသို့ သေနတ်ဝန် မင်းကျော် ပျံချီ, မင်းလှရွှေတောင်တို့ ချီလေရာ သူရဲသူခက် လက်နက်ပါ ချေသောကြောင့် ခပ်မဆိတ် နေတော်မူ၏။ | M40: At that time, although the Alaungmintayagyi Phaya heard that the four commanders and four units that had marched ahead along the western Mu route had reached the Nyaunghla area, because the Thanatwun Minkyawpyanchi and Minhlashwetaung had marched to Ywathitgyi with soldiers and weapons, he remained silent.
A41: First 5% | B41: vol1 | C41: 77 | D41: vol1_s000480 | E41: vol1_s000480_t02_8b3494957d0f | F41: Alaungpaya | G41: EXERCISED_STRATEGIC_PATIENCE | H41: Military operations | I41: supported | J41: Supported by the Burmese sentence and allowed narrative context; grouping and contextually inferred participants accepted. | L41: ယင်းသောအခါ အနောက်ဘက် မူးကြောင်း အလျင်ချီနှင့်ရသည့် လေးဗိုလ်လေးတပ်တို့ ညောင်လှအရပ်သို့ ရောက်ကြောင်းကို အလောင်းမင်းတရားကြီးဘုရား ကြားတော်မူသော်လည်း ရွာသစ်ကြီးသို့ သေနတ်ဝန် မင်းကျော် ပျံချီ, မင်းလှရွှေတောင်တို့ ချီလေရာ သူရဲသူခက် လက်နက်ပါ ချေသောကြောင့် ခပ်မဆိတ် နေတော်မူ၏။ | M41: At that time, although the Alaungmintayagyi Phaya heard that the four commanders and four units that had marched ahead along the western Mu route had reached the Nyaunghla area, because the Thanatwun Minkyawpyanchi and Minhlashwetaung had marched to Ywathitgyi with soldiers and weapons, he remained silent.
